Traceback (most recent call last):
  File "/home/jubayer/anaconda3/envs/dsn-template/lib/python3.7/site-packages/jupyter_cache/executors/utils.py", line 56, in single_nb_execution
    record_timing=False,
  File "/home/jubayer/anaconda3/envs/dsn-template/lib/python3.7/site-packages/nbclient/client.py", line 1082, in execute
    return NotebookClient(nb=nb, resources=resources, km=km, **kwargs).execute()
  File "/home/jubayer/anaconda3/envs/dsn-template/lib/python3.7/site-packages/nbclient/util.py", line 74, in wrapped
    return just_run(coro(*args, **kwargs))
  File "/home/jubayer/anaconda3/envs/dsn-template/lib/python3.7/site-packages/nbclient/util.py", line 53, in just_run
    return loop.run_until_complete(coro)
  File "/home/jubayer/anaconda3/envs/dsn-template/lib/python3.7/asyncio/base_events.py", line 587, in run_until_complete
    return future.result()
  File "/home/jubayer/anaconda3/envs/dsn-template/lib/python3.7/site-packages/nbclient/client.py", line 536, in async_execute
    cell, index, execution_count=self.code_cells_executed + 1
  File "/home/jubayer/anaconda3/envs/dsn-template/lib/python3.7/site-packages/nbclient/client.py", line 827, in async_execute_cell
    self._check_raise_for_error(cell, exec_reply)
  File "/home/jubayer/anaconda3/envs/dsn-template/lib/python3.7/site-packages/nbclient/client.py", line 735, in _check_raise_for_error
    raise CellExecutionError.from_cell_and_msg(cell, exec_reply['content'])
nbclient.exceptions.CellExecutionError: An error occurred while executing the following cell:
------------------
seq1 = basecount(seq1)
seq2 = basecount(seq2)
------------------

[0;31m---------------------------------------------------------------------------[0m
[0;31mAttributeError[0m                            Traceback (most recent call last)
[0;32m<ipython-input-27-edad7b34f717>[0m in [0;36m<module>[0;34m[0m
[1;32m      1[0m [0mseq1[0m [0;34m=[0m [0mbasecount[0m[0;34m([0m[0mseq1[0m[0;34m)[0m[0;34m[0m[0;34m[0m[0m
[0;32m----> 2[0;31m [0mseq2[0m [0;34m=[0m [0mbasecount[0m[0;34m([0m[0mseq2[0m[0;34m)[0m[0;34m[0m[0;34m[0m[0m
[0m
[0;32m<ipython-input-19-99955a37b3c7>[0m in [0;36mbasecount[0;34m(seq, useall, calfreqs_pc)[0m
[1;32m     16[0m [0;34m[0m[0m
[1;32m     17[0m     [0;32mfor[0m [0mletter[0m [0;32min[0m [0mseqset[0m[0;34m:[0m[0;34m[0m[0;34m[0m[0m
[0;32m---> 18[0;31m         [0mnum[0m [0;34m=[0m [0mseq[0m[0;34m.[0m[0mcount[0m[0;34m([0m[0mletter[0m[0;34m)[0m[0;34m[0m[0;34m[0m[0m
[0m[1;32m     19[0m         [0;32mif[0m [0mcalfreqs_pc[0m[0;34m:[0m[0;34m[0m[0;34m[0m[0m
[1;32m     20[0m             [0mpc[0m [0;34m=[0m [0mnum[0m [0;34m/[0m [0mlength[0m[0;34m[0m[0;34m[0m[0m

[0;31mAttributeError[0m: 'dict' object has no attribute 'count'
AttributeError: 'dict' object has no attribute 'count'

